Workbook
Name EnvasadoFrascos: #REF!
Name EnvasadoFrascos: #REF!
Name EnvasadoFrascos: #REF!
Name EnvasadoFrascos: #REF!
Name EnvasadoFrascos: #REF!

Sheet Ternum tubos
B2: Datos
B3: Cliente | C3: TERNUM
B4: Producto
B5: Servicio | C5: Envasado
B6: Materiales Lab. Coper
B7: Envase | C7: Ovales | D7: Ovales | E7: Ovales | F7: Ovales | G7: Airless | H7: Airless
B8: Capacidad envase (ml): | C8: 50 | D8: 50 | E8: 100 | F8: 100 | G8: 50 | H8: 50
B9: Unidades | C9: 5000 | D9: 10000 | E9: 5000 | F9: 10000 | G9: 5000 | H9: 10000 | J9: Comentarios
B12: MO Planta Jumsa
B14: Tasa €/hora | C14: =+'BD tasas y precios'!$C$12 -> 32.2 | D14: =+'BD tasas y precios'!$C$12 -> 32.2 | E14: =+'BD tasas y precios'!$C$12 -> 32.2 | F14: =+'BD tasas y precios'!$C$12 -> 32.2 | G14: =+'BD tasas y precios'!$C$12 -> 32.2 | H14: =+'BD tasas y precios'!$C$12 -> 32.2
B16: Operación | C16: Envasado Tubo | D16: Envasado Tubo | E16: Envasado Tubo | F16: Envasado Tubo | G16: Envasado Tubo | H16: Envasado Tubo | J16: Si son 9K uds se buscar en el rango 5 k a 10 k
B17: Tiempo (horas) | C17: n.d. | D17: n.d. | E17: n.d. | F17: n.d. | G17: n.d. | H17: n.d. | J17: Sin tiempos ver tarifa directamente
B18: Tiempo (uds /hora) | C18: n.d. | D18: n.d. | E18: n.d. | F18: n.d. | G18: n.d. | H18: n.d. | J18: Los tubos no hay trazabilidad de formulas - entiendo que es mismo €/hora
B19: Unidad de referencia | C19: n.a. | D19: n.a. | E19: n.a. | F19: n.a. | G19: n.a. | H19: n.a.
B20: Personas | C20: 0 | D20: 0 | E20: 0 | F20: 0 | G20: 0 | H20: 0
B21: Tiempo (horas) | C21: n.a. | D21: n.a. | E21: n.a. | F21: n.a. | G21: n.a. | H21: n.a.
B22: €/ud tubo | C22: 0.1624 | D22: 0.1624 | E22: 0.168 | F22: 0.1554 | G22: 0.116 | H22: 0.104 | J22: El ultimo airless me da 105 , no es material
B23: Total (€/ ud) | C23: =+IF(C20>0,C22*1.85,C22) -> 0.1624 | D23: 0.146 | E23: =+IF(E20>0,E22*1.85,E22) -> 0.168 | F23: =+IF(F20>0,F22*1.85,F22) -> 0.1554 | G23: =+IF(G20>0,G22*1.85,G22) -> 0.116 | H23: =+IF(H20>0,H22*1.85,H22) -> 0.104
B25: Operación | C25: Envasado Estándar | D25: Envasado Estándar | E25: Envasado Estándar | F25: Envasado Estándar | G25: Envasado Estándar | H25: Envasado Estándar
B26: Tiempo (horas)
B27: Tiempo (uds /hora)
B28: Unidad de referencia
B29: Personas
B30: Tiempo (horas) | C30: =+IFERROR(IF(C26>0,C26*C29,C28/C27*C29),"") | D30: =+IFERROR(IF(D26>0,D26*D29,D28/D27*D29),"") | E30: =+IFERROR(IF(E26>0,E26*E29,E28/E27*E29),"") | F30: =+IFERROR(IF(F26>0,F26*F29,F28/F27*F29),"") | G30: =+IFERROR(IF(G26>0,G26*G29,G28/G27*G29),"") | H30: =+IFERROR(IF(H26>0,H26*H29,H28/H27*H29),"")
B31: €/ud tubo
B32: Total (€/ ud) | C32: =+IFERROR(($C$14*C30)/C9,"") | D32: =+IFERROR(($C$14*D30)/D9,"") | E32: =+IFERROR(($C$14*E30)/E9,"") | F32: =+IFERROR(($C$14*F30)/F9,"") | G32: =+IFERROR(($C$14*G30)/G9,"") | H32: =+IFERROR(($C$14*H30)/H9,"")
B34: Operación | C34: Estuchado | D34: Estuchado | E34: Estuchado | F34: Estuchado | G34: Estuchado | H34: Estuchado
B35: Tiempo (horas)
B36: Tiempo (uds /hora)
B37: Unidad de referencia
B38: Personas
B39: Tiempo (horas) | C39: =+IFERROR(IF(C35>0,C35*C38,C37/C36*C38),"") | D39: =+IFERROR(IF(D35>0,D35*D38,D37/D36*D38),"") | E39: =+IFERROR(IF(E35>0,E35*E38,E37/E36*E38),"") | F39: =+IFERROR(IF(F35>0,F35*F38,F37/F36*F38),"")
B40: €/ud tubo
B41: Total (€/ ud) | C41: =+IFERROR(($C$14*C39)/C9,"") | D41: =+IFERROR(($C$14*D39)/D9,"") | E41: =+IFERROR(($C$14*E39)/E9,"") | F41: =+IFERROR(($C$14*F39)/F9,"")
B43: Operación | C43: Env. + Est. | D43: Env. + Est. | E43: Env. + Est. | F43: Env. + Est. | G43: Env. + Est. | H43: Env. + Est.
B44: Tiempo (horas)
B45: Tiempo (uds /hora)
B46: Unidad de referencia
B47: Personas
B48: Tiempo (horas) | C48: =+IFERROR(IF(C44>0,C44*C47,C46/C45*C47),"") | D48: =+IFERROR(IF(D44>0,D44*D47,D46/D45*D47),"") | E48: =+IFERROR(IF(E44>0,E44*E47,E46/E45*E47),"") | F48: =+IFERROR(IF(F44>0,F44*F47,F46/F45*F47),"")
...

Sheet Mesobeauty
C2: Presp | E2: 476/25
C3: Datos
C4: Cliente | E4: MESOBEAUTY
C5: Producto | E5: EDT PROMOCIONAL 10ML.
C6: Servicio | E6: Bulk + Envs
C7: Materiales Lab. Coper
C8: Envase
C9: Capacidad envase (ml): | E9: 10 | G9: Es de 10 ml pero pone 11 ml para el calculo de coste coper
C10: Kilos | E10: 3000
C11: Unidades | E11: 300000 | G11: Comentarios
C14: Planta Coper
C17: MP
C19: Coste MP de la fórmula (€/kg) | E19: 5.12 | G19: Compras - escandallo Angel
C22: MO Planta Coper
C24: Elegir tarifa €/hora | E24: TARIFA 1 (FORMULACIONES HASTA 10€ MP)– 223
C25: Tasa €/hora 2026 | E25: 239 | G25: Parece ser tarifa 1 incrementada
C27: Tiempo de fabricación | E27: 675 | G27: Escandallo Angel | I27: Puede incluir tiempo de pesada , fabricación, maceración, enfriamento, análisis, limpieza y ajuste de color
C29: Total MO (€/kg) | E29: =+(E27/60)*(E25/E10) -> 0.89625
C32: Otros conceptos planta Coper
C34: Análisis Bacterias | E34: 0
C35: Análisis Mohos y Levaduras | E35: 0
C36: Nº de Bidones de 100 kg (uds) | E36: 0
C37: Nº de Bidones de 1000 kg | E37: 3
C38: Nº de palets | E38: 2
C39: Nº de transportes | E39: 3 | G39: Cuanto lleva cada transporte?
C41: Analisis bacterias (€/kg) | E41: =+E34*'BD tasas y precios'!C30/E10 -> 0
C42: Analisis Mohos y levaduras (€/kg) | E42: =+E35*'BD tasas y precios'!C29/E10 -> 0
C43: Bidon 100kg (€/kg) | E43: =+'BD tasas y precios'!C28*E36/E10 -> 0
C44: Bidon 1000k (€/kg) | E44: =+'BD tasas y precios'!C27*E37/E10 -> 0.21
C45: Palet euro. (€/kg) | E45: =+'BD tasas y precios'!C26*E38/E10 -> 0 | G45: No se porque no cotiza el palet
C46: Transporte a Jumsa (€/Kg) | E46: =+'BD tasas y precios'!C25*E39/E10 -> 0.017
C48: Total otros conceptos (€/kg) | E48: =+SUM(E41,E42,E43,E44,E45,E46) -> 0.227
C51: Total planta Coper
C53: Coste Mp | E53: =+E19 -> 5.12
C54: Coste Mo | E54: =+E29 -> 0.89625
C55: Coste otros | E55: =+E48 -> 0.227
C56: Subtotal (Mp + MO +Otros) (€/Kg) | E56: =+SUM(E53,E54,E55) -> 6.24325
C58: Porcentaje de merma (%) | E58: 0.03 | G58: Vincular Formules
C60: Merma (€/kg) | E60: =+E56*E58 -> 0.1872975
C62: Porcentaje de residuos (%) | E62: 0.05 | G62: Vincular Formules
...

Sheet Modelo FS
C2: Presp | E2: 476/25
C3: Datos
C4: Cliente
C5: Producto
C6: Servicio
C7: Materiales Lab. Coper
C8: Envase
C9: Capacidad envase (ml):
C10: Kilos
C11: Unidades | G11: Comentarios
C14: Planta Coper
C17: MP
C19: Coste MP de la fórmula (€/kg) | G19: Hay que seleccionar del escandallo los tiempos en función del escalado
C22: MO Planta Coper
C24: Elegir tarifa €/hora | E24: TARIFA 1 (FORMULACIONES HASTA 10€ MP)– 223
C25: Tasa €/hora 2026 | E25: =+VLOOKUP(E24,'BD tasas y precios'!B3:E7,2,0) -> 223
C27: Tiempo de fabricación
C29: Total MO (€/kg) | E29: =+IFERROR((E27/60)*(E25/E10),"")
C32: Otros conceptos planta Coper
C34: Análisis Bacterias | E34: 0
C35: Análisis Mohos y Levaduras | E35: 0
C36: Nº de Bidones de 100 kg (uds) | E36: 0
C37: Nº de Bidones de 1000 kg | E37: 0
C38: Nº de palets | E38: 0
C39: Nº de transportes | E39: 0
C41: Analisis bacterias (€/kg) | E41: =+IFERROR(E34*'BD tasas y precios'!C30/E10,"")
C42: Analisis Mohos y levaduras (€/kg) | E42: =+IFERROR(E35*'BD tasas y precios'!C29/E10,"")
C43: Bidon 100kg (€/kg) | E43: =+IFERROR('BD tasas y precios'!C28*E36/E10,"")
C44: Bidon 1000k (€/kg) | E44: =+IFERROR('BD tasas y precios'!C27*E37/E10,"")
C45: Palet euro. (€/kg) | E45: =+IFERROR('BD tasas y precios'!C26*E38/E10,"")
C46: Transporte a Jumsa (€/Kg) | E46: =+IFERROR('BD tasas y precios'!C25*E39/E10,"")
C48: Total otros conceptos (€/kg) | E48: =+SUM(E41,E42,E43,E44,E45,E46) -> 0
C51: Total planta Coper
C53: Coste Mp | E53: =+E19 -> 0
C54: Coste Mo | E54: =+E29
C55: Coste otros | E55: =+E48 -> 0
C56: Subtotal (Mp + MO +Otros) (€/Kg) | E56: =+SUM(E53,E54,E55) -> 0
C58: Porcentaje de merma (%) | E58: 0 | G58: Vincular a BD
C60: Merma (€/kg) | E60: =+E56*E58 -> 0
C62: Porcentaje de residuos (%) | E62: 0 | G62: Vincular a BD
...

Sheet DB >>

Sheet TD tarifas
B3: DB ENVASADO TUBO
B5: Operación | C5: Envasado Tubos
B6: Tipo envase | C6: Estándar
B7: Capcidad (ml) | C7: 15
B8: Cantidad | C8: 20000
B10: € / ud. | C10: € / millar ud.
B11: 0.089 | C11: 89
B14: DB ENVASADO, ESTUCHADO Y ETIQUETADO
B16: Operación | C16: Envasado
B17: Envase | C17: Frascos
B18: Capcidad (ml) | C18: De 30 a 60
B19: Tipo envase | C19: Estándar
B21: Etiquetas de fila | C21: Unidades | D21: Pers. | E21: Tiempo (horas) | F21: Tiempo (uds /hora) | G21: Coste unidad Tarifas
B22: 500 unid. | C22: 500 | D22: 3.5 | E22: 2.5 | G22: 0.5635
B23: 1000 unid. | C23: 1000 | D23: 3.5 | E23: 3 | G23: 0.3381
B24: 1500 a 2500 unid | C24: 1500 | D24: 3.5 | F24: 500 | G24: 0.2254
B25: 2501 a 5000 unid. | C25: 3000 | D25: 3.5 | F25: 600 | G25: 0.18783333
B26: 5001 a 15000 unid. | C26: 15000 | D26: 3.5 | F26: 700 | G26: 0.161
B27: Total general | C27: 21000 | D27: 17.5 | E27: 5.5 | F27: 1800 | G27: 1.4758333

Sheet BD tasas y precios
B3: Tasas Coper (€/hora) | C3: 2024 | D3: 2025 | E3: 2026
B4: TARIFA 1 (FORMULACIONES HASTA 10€ MP)– 223 | C4: 223 | D4: =+C4*1.035 -> 230.805 | E4: =+D4*1.03 -> 237.72915
B5: TARIFA 2 (FORMULACIONES SUPERIORES A 10€ MP – 274 | C5: 274 | D5: =+C5*1.035 -> 283.59 | E5: =+D5*1.03 -> 292.0977
B6: TARIFA 3 (FORMULACIONES DE MAS DE 20€ MP - 325 | C6: 325 | D6: =+C6*1.035 -> 336.375 | E6: =+D6*1.03 -> 346.46625
B7: TARIFA 4 (FORMULACIONES DE MAS DE 30€ MP - 440 | C7: 440 | D7: =+C7*1.035 -> 455.4 | E7: =+D7*1.03 -> 469.062
B11: Tasas Jumsa (€/Hora) | C11: 2024 | D11: 2025 | E11: 2026
C12: 32.2 | D12: 32.2 | E12: 32.2
B15: Tabla precios escandallo Angel - otros conceptos
B16: Garrafa 60L (€) | C16: 20
B17: Cubo 10L (€) | C17: 5
B18: Bidon 60L (€) | C18: 20
B19: Deposito 100L (€) | C19: 140 | D19: 1
B20: Palet (€) | C20: 0
B21: Transporte a Jumsa (€) | C21: 10 | D21: A jumsa
B24: Tabla precios varios
B25: Precio transporte a JUMSA (€) | C25: 17
B26: Precio euro palet (€) | C26: 0
B27: Precio contenedor 1000 kg (€) | C27: 210
B28: Precio Bidon 100 kg (€) | C28: 26
B29: Precio analisis Mohoos Y levaduras (€) | C29: 68
B30: Precio analisis bacterias (€) | C30: 42
B33: Porcentaje Merma | C33: 70
B34: Merma > 70Kgs | C34: 0.08
B35: Merma 70 < 1500 | C35: 0.05
B39: Porcentaje Residuos
B40: Según Kilos
B41: General | C41: 0.025
B42: 150 | C42: 0.03
B43: 500 | C43: 0.03
B44: 1000 | C44: 0.03
B45: 1500 | C45: 0.03
B46: 2500 | C46: 0.03
B47: 3000 | C47: 0.03
B48: 4000 | C48: 0.03
B54: Tabla selección Si/No
B55: Si
B56: No

Sheet BD Jumsa
M1: ='BD tasas y precios'!E12 -> 32.2
A2: Envase | B2: Tipo envase | C2: Capcidad min (ml) | D2: Capcidad max (ml) | E2: Operación | F2: Escalado min (uds) | G2: Escalado max (uds) | H2: Cantidad | I2: Personas | J2: Tiempo (h) | K2: Piezas /hora | L2: Total horas | M2: Coste operación | N2: Coste unidad | O2: Coste Millar | P2: Turnos
A3: Frascos | B3: Estándar | C3: 0 | D3: 25 | E3: Etiquetado cilíndrico plastico | F3: 0 | G3: 500 | H3: 500 | I3: 1.5 | J3: 1 | L3: =+I3*J3 -> 1.5 | M3: =+L3*$M$1 -> 48.3 | N3: =+M3/H3 -> 0.0966 | O3: =+N3*1000 -> 96.6 | P3: =+J3/8 -> 0.125 | R3: Que era el 1400 en vermell??
A4: Frascos | B4: Estándar | C4: 0 | D4: 25 | E4: Etiquetado plano plástico | F4: 0 | G4: 500 | H4: 500 | I4: 1.5 | J4: 1.5 | L4: =+I4*J4 -> 2.25 | M4: =+L4*$M$1 -> 72.45 | N4: =+M4/H4 -> 0.1449 | O4: =+N4*1000 -> 144.9 | P4: =+J4/8 -> 0.1875 | R4: Lo de rollon 1 pax más es en todas??
A5: Frascos | B5: Frascos Agrafados | C5: 0 | D5: 25 | E5: Etiquetado cilíndrico plastico | F5: 0 | G5: 500 | H5: 500 | I5: 1.5 | J5: 1.5 | L5: =+I5*J5 -> 2.25 | M5: =+L5*$M$1 -> 72.45 | N5: =+M5/H5 -> 0.1449 | O5: =+N5*1000 -> 144.9 | P5: =+J5/8 -> 0.1875
A6: Frascos | B6: Frascos Agrafados | C6: 0 | D6: 25 | E6: Etiquetado plano plástico | F6: 0 | G6: 500 | H6: 500 | I6: 1.5 | J6: 1.5 | L6: =+I6*J6 -> 2.25 | M6: =+L6*$M$1 -> 72.45 | N6: =+M6/H6 -> 0.1449 | O6: =+N6*1000 -> 144.9 | P6: =+J6/8 -> 0.1875
A7: Frascos | B7: Frascos Agrafados | C7: 0 | D7: 25 | E7: Etiquetado plano vidrio | F7: 0 | G7: 500 | H7: 500 | I7: 1.5 | J7: 2.5 | L7: =+I7*J7 -> 3.75 | M7: =+L7*$M$1 -> 120.75 | N7: =+M7/H7 -> 0.2415 | O7: =+N7*1000 -> 241.5 | P7: =+J7/8 -> 0.3125
A8: Frascos | B8: Estándar | C8: 0 | D8: 25 | E8: Etiquetado cilíndrico vidrio | F8: 0 | G8: 500 | H8: 500 | I8: 2.5 | J8: 1 | L8: =+I8*J8 -> 2.5 | M8: =+L8*$M$1 -> 80.5 | N8: =+M8/H8 -> 0.161 | O8: =+N8*1000 -> 161 | P8: =+J8/8 -> 0.125
A9: Frascos | B9: Estándar | C9: 0 | D9: 25 | E9: Etiquetado plano vidrio | F9: 0 | G9: 500 | H9: 500 | I9: 2.5 | J9: 1.5 | L9: =+I9*J9 -> 3.75 | M9: =+L9*$M$1 -> 120.75 | N9: =+M9/H9 -> 0.2415 | O9: =+N9*1000 -> 241.5 | P9: =+J9/8 -> 0.1875
A10: Frascos | B10: Frascos Agrafados | C10: 0 | D10: 25 | E10: Etiquetado cilíndrico vidrio | F10: 0 | G10: 500 | H10: 500 | I10: 2.5 | J10: 1.5 | L10: =+I10*J10 -> 3.75 | M10: =+L10*$M$1 -> 120.75 | N10: =+M10/H10 -> 0.2415 | O10: =+N10*1000 -> 241.5 | P10: =+J10/8 -> 0.1875
A11: Frascos | B11: Estándar | C11: 0 | D11: 25 | E11: Envasado | F11: 0 | G11: 500 | H11: 500 | I11: 3.5 | J11: 2.5 | L11: =+I11*J11 -> 8.75 | M11: =+L11*$M$1 -> 281.75 | N11: =+M11/H11 -> 0.5635 | O11: =+N11*1000 -> 563.5 | P11: =+J11/8 -> 0.3125
A12: Frascos | B12: Estándar | C12: 0 | D12: 25 | E12: Envasado + estuchado | F12: 0 | G12: 500 | H12: 500 | I12: 4.5 | J12: 2.5 | L12: =+I12*J12 -> 11.25 | M12: =+L12*$M$1 -> 362.25 | N12: =+M12/H12 -> 0.7245 | O12: =+N12*1000 -> 724.5 | P12: =+J12/8 -> 0.3125
A13: Frascos | B13: Frascos Agrafados | C13: 0 | D13: 25 | E13: Envasado | F13: 0 | G13: 500 | H13: 500 | I13: 4.5 | J13: 2.5 | L13: =+I13*J13 -> 11.25 | M13: =+L13*$M$1 -> 362.25 | N13: =+M13/H13 -> 0.7245 | O13: =+N13*1000 -> 724.5 | P13: =+J13/8 -> 0.3125
A14: Frascos | B14: Estándar | C14: 0 | D14: 25 | E14: Estuchado | F14: 0 | G14: 500 | H14: 500 | I14: 3.5 | J14: 1 | L14: =+I14*J14 -> 3.5 | M14: =+L14*$M$1 -> 112.7 | N14: =+M14/H14 -> 0.2254 | O14: =+N14*1000 -> 225.4 | P14: =+J14/8 -> 0.125
A15: Tarros | B15: Estándar | C15: 151 | D15: 300 | E15: Etiquetado cilíndrico plastico | F15: 0 | G15: 500 | H15: 500 | I15: 1.5 | J15: 1.5 | L15: =+I15*J15 -> 2.25 | M15: =+L15*$M$1 -> 72.45 | N15: =+M15/H15 -> 0.1449 | O15: =+N15*1000 -> 144.9 | P15: =+J15/8 -> 0.1875
A16: Tarros | B16: Estándar | C16: 301 | D16: 500 | E16: Etiquetado cilíndrico plastico | F16: 0 | G16: 500 | H16: 500 | I16: 1.5 | J16: 1.5 | L16: =+I16*J16 -> 2.25 | M16: =+L16*$M$1 -> 72.45 | N16: =+M16/H16 -> 0.1449 | O16: =+N16*1000 -> 144.9 | P16: =+J16/8 -> 0.1875
... A19: Frascos | B19: Frascos Agrafados | C19: 0 | D19: 25 | E19: Envasado + estuchado | F19: 0 | G19: 500 | H19: 500 | I19: 5.5 | J19: 2.5 | L19: =+I19*J19 -> 13.75 | M19: =+L19*$M$1 -> 442.75 | N19: =+M19/H19 -> 0.8855 | O19: =+N19*1000 -> 885.5 | P19: =+J19/8 -> 0.3125
A20: Frascos | B20: Estándar | C20: 0 | D20: 25 | E20: Envasado Rollon | F20: 0 | G20: 500 | H20: 500 | I20: =+I4+1 -> 2.5 | J20: 2.5 | L20: =+I20*J20 -> 6.25 | M20: =+L20*$M$1 -> 201.25 | N20: =+M20/H20 -> 0.4025 | O20: =+N20*1000 -> 402.5 | P20: =+J20/8 -> 0.3125
A21: Frascos | B21: Estándar | C21: 0 | D21: 25 | E21: Envasado | F21: 501 | G21: 1000 | H21: 1000 | I21: 3.5 | J21: 3 | L21: =+I21*J21 -> 10.5 | M21: =+L21*$M$1 -> 338.1 | N21: =+M21/H21 -> 0.3381 | O21: =+N21*1000 -> 338.1 | P21: =+J21/8 -> 0.375
A22: Frascos | B22: Frascos Agrafados | C22: 0 | D22: 25 | E22: Envasado | F22: 501 | G22: 1000 | H22: 1000 | I22: 4.5 | J22: 3 | L22: =+I22*J22 -> 13.5 | M22: =+L22*$M$1 -> 434.7 | N22: =+M22/H22 -> 0.4347 | O22: =+N22*1000 -> 434.7 | P22: =+J22/8 -> 0.375
A23: Frascos | B23: Estándar | C23: 0 | D23: 25 | E23: Envasado Rollon | F23: 501 | G23: 1000 | H23: 1000 | I23: =+I19+1 -> 6.5 | J23: 3 | L23: =+I23*J23 -> 19.5 | M23: =+L23*$M$1 -> 627.9 | N23: =+M23/H23 -> 0.6279 | O23: =+N23*1000 -> 627.9 | P23: =+J23/8 -> 0.375
A24: Frascos | B24: Frascos Agrafados | C24: 0 | D24: 25 | E24: Estuchado con interior | F24: 0 | G24: 500 | H24: 500 | I24: 4.5 | J24: 1.5 | L24: =+I24*J24 -> 6.75 | M24: =+L24*$M$1 -> 217.35 | N24: =+M24/H24 -> 0.4347 | O24: =+N24*1000 -> 434.7 | P24: =+J24/8 -> 0.1875
A25: Frascos | B25: Estándar | C25: 0 | D25: 25 | E25: Envasado | F25: 1001 | G25: 2500 | H25: 2500 | I25: 3.5 | K25: 600 | L25: =I25*(H25/K25) -> 14.583333 | M25: =+L25*$M$1 -> 469.58333 | N25: =+M25/H25 -> 0.18783333 | O25: =+N25*1000 -> 187.83333 | P25: =+J25/8 -> 0
A26: Frascos | B26: Frascos Agrafados | C26: 0 | D26: 25 | E26: Envasado | F26: 1001 | G26: 2500 | H26: 2500 | I26: 4.5 | K26: 425 | L26: =I26*(H26/K26) -> 26.470588 | M26: =+L26*$M$1 -> 852.35294 | N26: =+M26/H26 -> 0.34094118 | O26: =+N26*1000 -> 340.94118 | P26: =+J26/8 -> 0
A27: Frascos | B27: Estándar | C27: 0 | D27: 25 | E27: Envasado Rollon | F27: 1001 | G27: 2500 | H27: 2500 | I27: =+I21+1 -> 4.5 | K27: 600 | L27: =I27*(H27/K27) -> 18.75 | M27: =+L27*$M$1 -> 603.75 | N27: =+M27/H27 -> 0.2415 | O27: =+N27*1000 -> 241.5 | P27: =+J27/8 -> 0
A28: Frascos | B28: Estándar | C28: 0 | D28: 25 | E28: Envasado | F28: 2501 | G28: 5000 | H28: 5000 | I28: 3.5 | K28: 700 | L28: =I28*(H28/K28) -> 25 | M28: =+L28*$M$1 -> 805 | N28: =+M28/H28 -> 0.161 | O28: =+N28*1000 -> 161 | P28: =+J28/8 -> 0
A29: Frascos | B29: Frascos Agrafados | C29: 0 | D29: 25 | E29: Envasado | F29: 2501 | G29: 5000 | H29: 5000 | I29: 4.5 | K29: 450 | L29: =I29*(H29/K29) -> 50 | M29: =+L29*$M$1 -> 1610 | N29: =+M29/H29 -> 0.322 | O29: =+N29*1000 -> 322 | P29: =+J29/8 -> 0
A30: Frascos | B30: Estándar | C30: 0 | D30: 25 | E30: Envasado Rollon | F30: 2501 | G30: 5000 | H30: 5000 | I30: =+I24+1 -> 5.5 | K30: 700 | L30: =I30*(H30/K30) -> 39.285714 | M30: =+L30*$M$1 -> 1265 | N30: =+M30/H30 -> 0.253 | O30: =+N30*1000 -> 253 | P30: =+J30/8 -> 0
A31: Frascos | B31: Frascos Agrafados | C31: 0 | D31: 25 | E31: Envasado | F31: 5001 | G31: 10000 | H31: 10000 | I31: 4.5 | K31: 500 | L31: =I31*(H31/K31) -> 90 | M31: =+L31*$M$1 -> 2898 | N31: =+M31/H31 -> 0.2898 | O31: =+N31*1000 -> 289.8 | P31: =+J31/8 -> 0
A32: Frascos | B32: Estándar | C32: 0 | D32: 25 | E32: Etiquetado cilíndrico plastico | F32: 501 | G32: 1000 | H32: 1000 | I32: 1.5 | J32: 1.5 | L32: =+I32*J32 -> 2.25 | M32: =+L32*$M$1 -> 72.45 | N32: =+M32/H32 -> 0.07245 | O32: =+N32*1000 -> 72.45 | P32: =+J32/8 -> 0.1875
A33: Frascos | B33: Estándar | C33: 0 | D33: 25 | E33: Etiquetado plano plástico | F33: 501 | G33: 1000 | H33: 1000 | I33: 1.5 | J33: 2 | L33: =+I33*J33 -> 3 | M33: =+L33*$M$1 -> 96.6 | N33: =+M33/H33 -> 0.0966 | O33: =+N33*1000 -> 96.6 | P33: =+J33/8 -> 0.25
A34: Frascos | B34: Frascos Agrafados | C34: 0 | D34: 25 | E34: Etiquetado cilíndrico plastico | F34: 501 | G34: 1000 | H34: 1000 | I34: 1.5 | J34: 1.5 | L34: =+I34*J34 -> 2.25 | M34: =+L34*$M$1 -> 72.45 | N34: =+M34/H34 -> 0.07245 | O34: =+N34*1000 -> 72.45 | P34: =+J34/8 -> 0.1875
A35: Frascos | B35: Frascos Agrafados | C35: 0 | D35: 25 | E35: Etiquetado plano plástico | F35: 501 | G35: 1000 | H35: 1000 | I35: 1.5 | J35: 2.5 | L35: =+I35*J35 -> 3.75 | M35: =+L35*$M$1 -> 120.75 | N35: =+M35/H35 -> 0.12075 | O35: =+N35*1000 -> 120.75 | P35: =+J35/8 -> 0.3125
A36: Frascos | B36: Estándar | C36: 0 | D36: 25 | E36: Etiquetado cilíndrico vidrio | F36: 501 | G36: 1000 | H36: 1000 | I36: 2.5 | J36: 1.5 | L36: =+I36*J36 -> 3.75 | M36: =+L36*$M$1 -> 120.75 | N36: =+M36/H36 -> 0.12075 | O36: =+N36*1000 -> 120.75 | P36: =+J36/8 -> 0.1875
A37: Frascos | B37: Estándar | C37: 0 | D37: 25 | E37: Etiquetado plano vidrio | F37: 501 | G37: 1000 | H37: 1000 | I37: 2.5 | J37: 2 | L37: =+I37*J37 -> 5 | M37: =+L37*$M$1 -> 161 | N37: =+M37/H37 -> 0.161 | O37: =+N37*1000 -> 161 | P37: =+J37/8 -> 0.25
A38: Tarros | B38: Estándar | C38: 151 | D38: 300 | E38: Etiquetado cilíndrico vidrio | F38: 0 | G38: 500 | H38: 500 | I38: 2.5 | J38: 1.5 | L38: =+I38*J38 -> 3.75 | M38: =+L38*$M$1 -> 120.75 | N38: =+M38/H38 -> 0.2415 | O38: =+N38*1000 -> 241.5 | P38: =+J38/8 -> 0.1875
A39: Tarros | B39: Estándar | C39: 301 | D39: 500 | E39: Etiquetado cilíndrico vidrio | F39: 0 | G39: 500 | H39: 500 | I39: 2.5 | J39: 1.5 | L39: =+I39*J39 -> 3.75 | M39: =+L39*$M$1 -> 120.75 | N39: =+M39/H39 -> 0.2415 | O39: =+N39*1000 -> 241.5 | P39: =+J39/8 -> 0.1875
A40: Tarros | B40: Estándar | C40: 501 | D40: 1000 | E40: Etiquetado cilíndrico vidrio | F40: 0 | G40: 500 | H40: 500 | I40: 2.5 | J40: 1.5 | L40: =+I40*J40 -> 3.75 | M40: =+L40*$M$1 -> 120.75 | N40: =+M40/H40 -> 0.2415 | O40: =+N40*1000 -> 241.5 | P40: =+J40/8 -> 0.1875
A41: Frascos | B41: Frascos Agrafados | C41: 0 | D41: 25 | E41: Etiquetado cilíndrico vidrio | F41: 501 | G41: 1000 | H41: 1000 | I41: 2.5 | J41: 1.5 | L41: =+I41*J41 -> 3.75 | M41: =+L41*$M$1 -> 120.75 | N41: =+M41/H41 -> 0.12075 | O41: =+N41*1000 -> 120.75 | P41: =+J41/8 -> 0.1875
A42: Frascos | B42: Frascos Agrafados | C42: 0 | D42: 25 | E42: Etiquetado plano vidrio | F42: 501 | G42: 1000 | H42: 1000 | I42: 2.5 | J42: 2.5 | L42: =+I42*J42 -> 6.25 | M42: =+L42*$M$1 -> 201.25 | N42: =+M42/H42 -> 0.20125 | O42: =+N42*1000 -> 201.25 | P42: =+J42/8 -> 0.3125
...

Sheet BD Tubos
R1: ='BD tasas y precios'!E12 -> 32.2
B2: Envase | C2: Tipo envase | D2: Capacidad min (ml) | E2: Capacidad max (ml) | F2: Operación | G2: Escalado min (uds) | H2: Escalado max (uds) | I2: Cantidad | J2: Personas | K2: Tiempo (h) | L2: Piezas /hora | M2: Total horas | N2: Coste operación | O2: Coste unidad | P2: Coste Millar | Q2: Turnos
B3: Tubos | C3: Elípticos (+85%) | D3: 0 | E3: 15 | F3: Envasado Tubos | G3: 0 | H3: 1000 | I3: 1000 | O3: =+P3/1000 -> 0.218 | P3: 218
B4: Tubos | C4: Elípticos (+85%) | D4: 0 | E4: 15 | F4: Envasado Tubos | G4: 1001 | H4: 2000 | I4: 2000 | O4: =+P4/1000 -> 0.375 | P4: 375
B5: Tubos | C5: Elípticos (+85%) | D5: 0 | E5: 15 | F5: Envasado Tubos | G5: 2001 | H5: 2500 | I5: 2500 | O5: =+P5/1000 -> 0.21 | P5: 210
B6: Tubos | C6: Elípticos (+85%) | D6: 0 | E6: 15 | F6: Envasado Tubos | G6: 3001 | H6: 5000 | I6: 5000 | O6: =+P6/1000 -> 0.156 | P6: 156
B7: Tubos | C7: Elípticos (+85%) | D7: 0 | E7: 15 | F7: Envasado Tubos | G7: 5001 | H7: 10000 | I7: 10000 | O7: =+P7/1000 -> 0.146 | P7: 146
B8: Tubos | C8: Elípticos (+85%) | D8: 0 | E8: 15 | F8: Envasado Tubos | G8: 10001 | H8: 20000 | I8: 20000 | O8: =+P8/1000 -> 0.127 | P8: 127
B9: Tubos | C9: Elípticos (+85%) | D9: 0 | E9: 15 | F9: Envasado Tubos | G9: 20001 | H9: 50000 | I9: 50000 | O9: =+P9/1000 -> 0.112 | P9: 112
B10: Tubos | C10: Elípticos (+85%) | D10: 0 | E10: 15 | F10: Envasado Tubos | G10: 50001 | H10: 999999 | I10: 100000 | O10: =+P10/1000 -> 0.375 | P10: 375
B11: Tubos | C11: Estándar | D11: 0 | E11: 15 | F11: Envasado Tubos | G11: 0 | H11: 1000 | I11: 1000 | O11: =+P11/1000 -> 0.207 | P11: 207
B12: Tubos | C12: Estándar | D12: 0 | E12: 15 | F12: Envasado Tubos | G12: 1001 | H12: 2000 | I12: 2000 | O12: =+P12/1000 -> 0.153 | P12: 153
B13: Tubos | C13: Estándar | D13: 0 | E13: 15 | F13: Envasado Tubos | G13: 2001 | H13: 2500 | I13: 2500 | O13: =+P13/1000 -> 0.132 | P13: 132
B14: Tubos | C14: Estándar | D14: 0 | E14: 15 | F14: Envasado Tubos | G14: 3001 | H14: 5000 | I14: 5000 | O14: =+P14/1000 -> 0.117 | P14: 117
... B63: Tubos | C63: Ovalado (+40%) | D63: 16 | E63: 30 | F63: Envasado Tubos | G63: 5001 | H63: 10000 | I63: 10000 | O63: =+P63/1000 -> 0.076 | P63: 76
B64: Tubos | C64: Ovalado (+40%) | D64: 16 | E64: 30 | F64: Envasado Tubos | G64: 10001 | H64: 20000 | I64: 20000 | O64: =+P64/1000 -> 0.4033 | P64: =+P3*1.85 -> 403.3
B65: Tubos | C65: Ovalado (+40%) | D65: 16 | E65: 30 | F65: Envasado Tubos | G65: 20001 | H65: 50000 | I65: 50000 | O65: =+P65/1000 -> 0.69375 | P65: =+P4*1.85 -> 693.75
B66: Tubos | C66: Ovalado (+40%) | D66: 16 | E66: 30 | F66: Envasado Tubos | G66: 50001 | H66: 999999 | I66: 100000 | O66: =+P66/1000 -> 0.3885 | P66: =+P5*1.85 -> 388.5
B67: Tubos | C67: Elípticos (+85%) | D67: 31 | E67: 50 | F67: Envasado Tubos | G67: 0 | H67: 1000 | I67: 1000 | O67: =+P67/1000 -> 0.2886 | P67: =+P6*1.85 -> 288.6
B68: Tubos | C68: Elípticos (+85%) | D68: 31 | E68: 50 | F68: Envasado Tubos | G68: 1001 | H68: 2000 | I68: 2000 | O68: =+P68/1000 -> 0.2701 | P68: =+P7*1.85 -> 270.1
B69: Tubos | C69: Elípticos (+85%) | D69: 31 | E69: 50 | F69: Envasado Tubos | G69: 2001 | H69: 2500 | I69: 2500 | O69: =+P69/1000 -> 0.23495 | P69: =+P8*1.85 -> 234.95
B70: Tubos | C70: Elípticos (+85%) | D70: 31 | E70: 50 | F70: Envasado Tubos | G70: 3001 | H70: 5000 | I70: 5000 | O70: =+P70/1000 -> 0.2072 | P70: =+P9*1.85 -> 207.2
B71: Tubos | C71: Elípticos (+85%) | D71: 31 | E71: 50 | F71: Envasado Tubos | G71: 5001 | H71: 10000 | I71: 10000 | O71: =+P71/1000 -> 0.69375 | P71: =+P10*1.85 -> 693.75
B72: Tubos | C72: Elípticos (+85%) | D72: 31 | E72: 50 | F72: Envasado Tubos | G72: 10001 | H72: 20000 | I72: 20000 | O72: =+P72/1000 -> 0.38295 | P72: =+P11*1.85 -> 382.95
B73: Tubos | C73: Elípticos (+85%) | D73: 31 | E73: 50 | F73: Envasado Tubos | G73: 20001 | H73: 50000 | I73: 50000 | O73: =+P73/1000 -> 0.28305 | P73: =+P12*1.85 -> 283.05
B74: Tubos | C74: Elípticos (+85%) | D74: 31 | E74: 50 | F74: Envasado Tubos | G74: 50001 | H74: 999999 | I74: 100000 | O74: =+P74/1000 -> 0.2442 | P74: =+P13*1.85 -> 244.2
B75: Tubos | C75: Estándar | D75: 31 | E75: 50 | F75: Envasado Tubos | G75: 0 | H75: 1000 | I75: 1000 | O75: =+P75/1000 -> 0.21645 | P75: =+P14*1.85 -> 216.45
... B124: Tubos | C124: Ovalado (+40%) | D124: 51 | E124: 75 | F124: Envasado Tubos | G124: 1001 | H124: 2000 | I124: 2000 | O124: =+P124/1000 -> 0.1406 | P124: =+P63*1.85 -> 140.6
B125: Tubos | C125: Ovalado (+40%) | D125: 51 | E125: 75 | F125: Envasado Tubos | G125: 2001 | H125: 2500 | I125: 2500 | O125: =+P125/1000 -> 0.4033 | P125: =+P3*1.85 -> 403.3
B126: Tubos | C126: Ovalado (+40%) | D126: 51 | E126: 75 | F126: Envasado Tubos | G126: 3001 | H126: 5000 | I126: 5000 | O126: =+P126/1000 -> 0.69375 | P126: =+P4*1.85 -> 693.75
B127: Tubos | C127: Ovalado (+40%) | D127: 51 | E127: 75 | F127: Envasado Tubos | G127: 5001 | H127: 10000 | I127: 10000 | O127: =+P127/1000 -> 0.3885 | P127: =+P5*1.85 -> 388.5
B128: Tubos | C128: Ovalado (+40%) | D128: 51 | E128: 75 | F128: Envasado Tubos | G128: 10001 | H128: 20000 | I128: 20000 | O128: =+P128/1000 -> 0.2886 | P128: =+P6*1.85 -> 288.6
B129: Tubos | C129: Ovalado (+40%) | D129: 51 | E129: 75 | F129: Envasado Tubos | G129: 20001 | H129: 50000 | I129: 50000 | O129: =+P129/1000 -> 0.2701 | P129: =+P7*1.85 -> 270.1
B130: Tubos | C130: Ovalado (+40%) | D130: 51 | E130: 75 | F130: Envasado Tubos | G130: 50001 | H130: 999999 | I130: 100000 | O130: =+P130/1000 -> 0.23495 | P130: =+P8*1.85 -> 234.95
B131: Tubos | C131: Elípticos (+85%) | D131: 76 | E131: 100 | F131: Envasado Tubos | G131: 0 | H131: 1000 | I131: 1000 | O131: =+P131/1000 -> 0.2072 | P131: =+P9*1.85 -> 207.2
B132: Tubos | C132: Elípticos (+85%) | D132: 76 | E132: 100 | F132: Envasado Tubos | G132: 1001 | H132: 2000 | I132: 2000 | O132: =+P132/1000 -> 0.69375 | P132: =+P10*1.85 -> 693.75
B133: Tubos | C133: Elípticos (+85%) | D133: 76 | E133: 100 | F133: Envasado Tubos | G133: 2001 | H133: 2500 | I133: 2500 | O133: =+P133/1000 -> 0.38295 | P133: =+P11*1.85 -> 382.95
B134: Tubos | C134: Elípticos (+85%) | D134: 76 | E134: 100 | F134: Envasado Tubos | G134: 3001 | H134: 5000 | I134: 5000 | O134: =+P134/1000 -> 0.28305 | P134: =+P12*1.85 -> 283.05
B135: Tubos | C135: Elípticos (+85%) | D135: 76 | E135: 100 | F135: Envasado Tubos | G135: 5001 | H135: 10000 | I135: 10000 | O135: =+P135/1000 -> 0.2442 | P135: =+P13*1.85 -> 244.2
B136: Tubos | C136: Elípticos (+85%) | D136: 76 | E136: 100 | F136: Envasado Tubos | G136: 10001 | H136: 20000 | I136: 20000 | O136: =+P136/1000 -> 0.21645 | P136: =+P14*1.85 -> 216.45
...

Sheet tarifas Word JUMSA 
A1: 2025 | E1: FRASCOS COSMETICA | L1: COSTE FIJO: (ENVASADO - 281 €) (ETIQUETADO - 96 €)
A2: FRASCOS COSMETICA CAPACIDAD 1ML A 25ML
C4: Etiquetado cilíndrico plastico | F4: Etiquetado cilíndrico vidrio | I4: Etiquetado plano plástico | L4: Etiquetado plano vidrio
Q5: Com juguen el salts
A6: 500 unid. | C6: 1hx1,5p | D6: =(1*1.5)*(32.2)/(500)*(1000) -> 96.6 | F6: 1hx2,5p | G6: =(1*2.5)*(32.2)/(500)*(1000) -> 161 | I6: 1,5hx1,5p | J6: =(1.5*1.5)*(32.2)/(500)*(1000) -> 144.9 | L6: 1,5hx2,5p | M6: =(1.5*2.5)*(32.2)/(500)*(1000) -> 241.5
A7: 1000 unid. | C7: 1,5hx1,5p | D7: =(1.5*1.5)*(32.2)/(1000)*(1000) -> 72.45 | F7: 1,5hx2,5p | G7: =(1.5*2.5)*(32.2)/(1000)*(1000) -> 120.75 | I7: 2hx1,5p | J7: =(2*1.5)*(32.2)/(1000)*(1000) -> 96.6 | L7: 2hx2,5p | M7: =(2*2.5)*(32.2)/(1000)*(1000) -> 161
A8: 1500 a 2500 unid | C8: 800h/1,5p | D8: =(1*1.5)*(32.2)/(800)*(1000) -> 60.375 | F8: 800h/2,5p | G8: =(1*2.5)*(32.2)/(800)*(1000) -> 100.625 | I8: 600h/1,5p | J8: =(1*1.5)*(32.2)/(600)*(1000) -> 80.5 | L8: 600h/2,5p | M8: =(1*2.5)*(32.2)/(600)*(1000) -> 134.16667
A9: 2501 a 5000 unid. | C9: 900h/1,5p | D9: =(1*1.5)*(32.2)/(900)*(1000) -> 53.666667 | F9: 900h/2,5p | G9: =(1*2.5)*(32.2)/(900)*(1000) -> 89.444444 | H9: ok | I9: 700h/1,5p | J9: =(1*1.5)*(32.2)/(700)*(1000) -> 69 | L9: 700h/2,5p | M9: =(1*2.5)*(32.2)/(700)*(1000) -> 115
A10: 5001 a 25000 unid. | C10: 1100h/1,5p | D10: =(1*1.5)*(32.2)/(1100)*(1000) -> 43.909091 | E10: 2000 | F10: 1100h/2,5p | G10: =(1*2.5)*(32.2)/(1100)*(1000) -> 73.181818 | I10: 1000h/1,5p | J10: =(1*1.5)*(32.2)/(1000)*(1000) -> 48.3 | L10: 1000h/2,5p | M10: =(1*2.5)*(32.2)/(1000)*(1000) -> 80.5
C13: Envasado | F13: Envasado + estuchado | I13: Estuchado
A15: 500 unid. | C15: 2,5h x 3,5p | D15: =(2.5*3.5)*(32.2)/(500)*(1000) -> 563.5 | F15: 2,5h x 4,5p | G15: =(2.5*4.5)*(32.2)/(500)*(1000) -> 724.5 | I15: 1h x 3,5p | J15: =(1*3.5)*(32.2)/(500)*(1000) -> 225.4
A16: 1000 unid. | C16: 3h x 3,5p | D16: =(3*3.5)*(32.2)/(1000)*(1000) -> 338.1 | F16: 3h x 4,5p | G16: =(3*4.5)*(32.2)/(1000)*(1000) -> 434.7 | I16: 1,5h x 3,5p | J16: =(1.5*3.5)*(32.2)/(1000)*(1000) -> 169.05
A17: 1500 a 2500 unid | C17: 600h/3,5p | D17: =(1*3.5)*(32.2)/(600)*(1000) -> 187.83333 | E17: OK | F17: 600h/4,5p | G17: =(1*4.5)*(32.2)/(600)*(1000) -> 241.5 | H17: 500 | I17: 700h/3,5p | J17: =(1*3.5)*(32.2)/(700)*(1000) -> 161
A18: 2501 a 5000 unid. | C18: 700h/3,5p | D18: =(1*3.5)*(32.2)/(700)*(1000) -> 161 | E18: ok | F18: 700h/4,5p | G18: =(1*4.5)*(32.2)/(700)*(1000) -> 207 | I18: 750h/3,5p | J18: =(1*3.5)*(32.2)/(750)*(1000) -> 150.26667 | Q18: Que son els vermells
A19: 5001 a 15000 unid. | C19: 800h/3,5p | D19: =(1*3.5)*(32.2)/(800)*(1000) -> 140.875 | F19: 800h/4,5p | G19: =(1*4.5)*(32.2)/(800)*(1000) -> 181.125 | H19: 750 | I19: 850h/3,5p | J19: =(1*3.5)*(32.2)/(850)*(1000) -> 132.58824 | K19: 800 | Q19: Que era el 1400 en vermell??
A20: 15000+ | B20: 1400 | C20: 1200h/4,5p | D20: =(1*4.5)*(32.2)/(1200)*(1000) -> 120.75 | Q20: Lo de rollon 1 pax más es en todas??
C21: rollon 1 persona más
A23: FRASCOS COSMETICA CAPACIDAD 30ML A 60ML
C25: Etiquetado cilíndrico plastico | F25: Etiquetado cilíndrico vidrio | I25: Etiquetado plano plástico | L25: Etiquetado plano vidrio
A27: 500 unid. | C27: 1hx1,5p | D27: =(1*1.5)*(32.2)/(500)*(1000) -> 96.6 | F27: 1hx2,5p | G27: =(1*2.5)*(32.2)/(500)*(1000) -> 161 | I27: 1,5hx1,5p | J27: =(1.5*1.5)*(32.2)/(500)*(1000) -> 144.9 | L27: 1,5hx2,5p | M27: =(1.5*2.5)*(32.2)/(500)*(1000) -> 241.5
A28: 1000 unid. | C28: 1,5hx1,5p | D28: =(1.5*1.5)*(32.2)/(1000)*(1000) -> 72.45 | F28: 1,5hx2,5p | G28: =(1.5*2.5)*(32.2)/(1000)*(1000) -> 120.75 | I28: 2hx1,5p | J28: =(2*1.5)*(32.2)/(1000)*(1000) -> 96.6 | L28: 2hx2,5p | M28: =(2*2.5)*(32.2)/(1000)*(1000) -> 161
A29: 1500 a 2500 unid | C29: 800h/1,5p | D29: =(1*1.5)*(32.2)/(800)*(1000) -> 60.375 | F29: 800h/2,5p | G29: =(1*2.5)*(32.2)/(800)*(1000) -> 100.625 | I29: 600h/1,5p | J29: =(1*1.5)*(32.2)/(600)*(1000) -> 80.5 | L29: 600h/2,5p | M29: =(1*2.5)*(32.2)/(600)*(1000) -> 134.16667
A30: 2501 a 5000 unid. | C30: 900h/1,5p | D30: =(1*1.5)*(32.2)/(900)*(1000) -> 53.666667 | F30: 900h/2,5p | G30: =(1*2.5)*(32.2)/(900)*(1000) -> 89.444444 | H30: 850 | I30: 700h/1,5p | J30: =(1*1.5)*(32.2)/(700)*(1000) -> 69 | L30: 700h/2,5p | M30: =(1*2.5)*(32.2)/(700)*(1000) -> 115
A31: 5001 a 25000 unid. | C31: 1100h/1,5p | D31: =(1*1.5)*(32.2)/(1100)*(1000) -> 43.909091 | F31: 1100h/2,5p | G31: =(1*2.5)*(32.2)/(1100)*(1000) -> 73.181818 | I31: 1000h/1,5p | J31: =(1*1.5)*(32.2)/(1000)*(1000) -> 48.3 | L31: 1000h/2,5p | M31: =(1*2.5)*(32.2)/(1000)*(1000) -> 80.5
C34: Envasado | F34: Envasado + estuchado | I34: Estuchado
A36: 500 unid. | C36: 2,5h x 3,5p | D36: =(2.5*3.5)*(32.2)/(500)*(1000) -> 563.5 | F36: 2,5h x 4,5p | G36: =(2.5*4.5)*(32.2)/(500)*(1000) -> 724.5 | I36: 1h x 3,5p | J36: =(1*3.5)*(32.2)/(500)*(1000) -> 225.4
A37: 1000 unid. | C37: 3h x 3,5p | D37: =(3*3.5)*(32.2)/(1000)*(1000) -> 338.1 | F37: 3h x 4,5p | G37: =(3*4.5)*(32.2)/(1000)*(1000) -> 434.7 | I37: 1,5h x 3,5p | J37: =(1.5*3.5)*(32.2)/(1000)*(1000) -> 169.05
A38: 1500 a 2500 unid | C38: 500h/3,5p | D38: =(1*3.5)*(32.2)/(500)*(1000) -> 225.4 | E38: 525h | F38: 500h/4,5p | G38: =(1*4.5)*(32.2)/(500)*(1000) -> 289.8 | H38: 525h | I38: 675h/3,5p | J38: =(1*3.5)*(32.2)/(675)*(1000) -> 166.96296
A39: 2501 a 5000 unid. | C39: 600h/3,5p | D39: =(1*3.5)*(32.2)/(600)*(1000) -> 187.83333 | E39: 625hi | F39: 600h/4,5p | G39: =(1*4.5)*(32.2)/(600)*(1000) -> 241.5 | H39: 625h | I39: 725h/3,5p | J39: =(1*3.5)*(32.2)/(725)*(1000) -> 155.44828 | K39: OK
A40: 5001 a 25000 unid. | C40: 700h/3,5p | D40: =(1*3.5)*(32.2)/(700)*(1000) -> 161 | E40: ok | F40: 700h/4,5p | G40: =(1*4.5)*(32.2)/(700)*(1000) -> 207 | H40: ok | I40: 825h/3,5p | J40: =(1*3.5)*(32.2)/(825)*(1000) -> 136.60606 | K40: 800
A41: AUTOMATICO | D41: 116 | Q41: que es automático???
A44: FRASCOS COSMETICA CAPACIDAD 75ML A 150ML
C46: Etiquetado cilíndrico plastico | F46: Etiquetado cilíndrico vidrio | I46: Etiquetado plano plástico | L46: Etiquetado plano vidrio
A48: 500 unid. | C48: 1,5hx1,5p | D48: =(1.5*1.5)*(32.2)/(500)*(1000) -> 144.9 | F48: 1,5hx2,5p | G48: =(1.5*2.5)*(32.2)/(500)*(1000) -> 241.5 | I48: 1,5hx1,5p | J48: =(1.5*1.5)*(32.2)/(500)*(1000) -> 144.9 | L48: 1,5hx2,5p | M48: =(1.5*2.5)*(32.2)/(500)*(1000) -> 241.5
A49: 1000 unid. | C49: 2hx1,5p | D49: =(2*1.5)*(32.2)/(1000)*(1000) -> 96.6 | F49: 2hx2,5p | G49: =(2*2.5)*(32.2)/(1000)*(1000) -> 161 | I49: 2,5hx1,5p | J49: =(2.5*1.5)*(32.2)/(1000)*(1000) -> 120.75 | L49: 2,5hx2,5p | M49: =(2.5*2.5)*(32.2)/(1000)*(1000) -> 201.25
A50: 1500 a 2500 unid | C50: 700h/1,5p | D50: =(1*1.5)*(32.2)/(700)*(1000) -> 69 | F50: 700h/2,5p | G50: =(1*2.5)*(32.2)/(700)*(1000) -> 115 | I50: 600h/1,5p | J50: =(1*1.5)*(32.2)/(600)*(1000) -> 80.5 | L50: 600h/2,5p | M50: =(1*2.5)*(32.2)/(600)*(1000) -> 134.16667
A51: 2501 a 5000 unid. | C51: 800h/1,5p | D51: =(1*1.5)*(32.2)/(800)*(1000) -> 60.375 | F51: 800h/2,5p | G51: =(1*2.5)*(32.2)/(800)*(1000) -> 100.625 | I51: 700h/1,5p | J51: =(1*1.5)*(32.2)/(700)*(1000) -> 69 | L51: 700h/2,5p | M51: =(1*2.5)*(32.2)/(700)*(1000) -> 115
A52: 5001 a 25000 unid. | C52: 1100h/1,5p | D52: =(1*1.5)*(32.2)/(1100)*(1000) -> 43.909091 | E52: ok | F52: 1100h/2,5p | G52: =(1*2.5)*(32.2)/(1100)*(1000) -> 73.181818 | I52: 1000h/1,5p | J52: =(1*1.5)*(32.2)/(1000)*(1000) -> 48.3 | L52: 1000h/2,5p | M52: =(1*2.5)*(32.2)/(1000)*(1000) -> 80.5
A53: *En el etiquetado cilindrico de vidrio en el escalado de 500 unidades se ha cambiado el tiempo de 1x2,5p a 1,5x2,5p para que el importe no sea igual que el escalado de 1000 unid
C55: Envasado | F55: Envasado + estuchado | I55: Estuchado | K55: c/interior (Mousse julia)
...

Sheet Tarifas Word Tubos (
B2: A PARTIR DE 75ml TIENE QUE IR BIEN COLOCADOS
B4: MAYENTIS TUBO 250Ml 3000 UNID. 218 € (2025)
B5: COSTE FIJO | D5: 375
B7: Capcidad (ml) | C7: Cantidad | D7: Precio (€) | E7: Precio unidad | F7: Elípticos | G7: Metálicos | H7: Pax adicional
B8: 250 | C8: 3000 | D8: 218 | E8: =+D8/C8 -> 0.072666667 | F8: =+D8*(1+0.85) -> 403.3 | G8: =+D8*(1+0.85) -> 403.3 | H8: 0.4
B9: 200 | C9: 1000 | D9: 375 | E9: =+D9/C9 -> 0.375 | F9: =+D9*(1+0.85) -> 693.75 | G9: =+D9*(1+0.85) -> 693.75 | H9: 0.4
B10: 200 | C10: 2000 | D10: 210 | E10: =+D10/C10 -> 0.105 | F10: =+D10*(1+0.85) -> 388.5 | G10: =+D10*(1+0.85) -> 388.5 | H10: 0.4
B11: 200 | C11: 2500 | D11: 156 | E11: =+D11/C11 -> 0.0624 | F11: =+D11*(1+0.85) -> 288.6 | G11: =+D11*(1+0.85) -> 288.6 | H11: 0.4
B12: 200 | C12: 5000 | D12: 146 | E12: =+D12/C12 -> 0.0292 | F12: =+D12*(1+0.85) -> 270.1 | G12: =+D12*(1+0.85) -> 270.1 | H12: 0.4
B13: 200 | C13: 10000 | D13: 127 | E13: =+D13/C13 -> 0.0127 | F13: =+D13*(1+0.85) -> 234.95 | G13: =+D13*(1+0.85) -> 234.95 | H13: 0.4
B14: 200 | C14: 20000 | D14: 112 | E14: =+D14/C14 -> 0.0056 | F14: =+D14*(1+0.85) -> 207.2 | G14: =+D14*(1+0.85) -> 207.2 | H14: 0.4
B15: 150 | C15: 1000 | D15: 375 | E15: =+D15/C15 -> 0.375 | F15: =+D15*(1+0.85) -> 693.75 | G15: =+D15*(1+0.85) -> 693.75 | H15: 0.4
B16: 150 | C16: 2000 | D16: 207 | E16: =+D16/C16 -> 0.1035 | F16: =+D16*(1+0.85) -> 382.95 | G16: =+D16*(1+0.85) -> 382.95 | H16: 0.4
B17: 150 | C17: 2500 | D17: 153 | E17: =+D17/C17 -> 0.0612 | F17: =+D17*(1+0.85) -> 283.05 | G17: =+D17*(1+0.85) -> 283.05 | H17: 0.4
B18: 150 | C18: 5000 | D18: 132 | E18: =+D18/C18 -> 0.0264 | F18: =+D18*(1+0.85) -> 244.2 | G18: =+D18*(1+0.85) -> 244.2 | H18: 0.4
B19: 150 | C19: 10000 | D19: 117 | E19: =+D19/C19 -> 0.0117 | F19: =+D19*(1+0.85) -> 216.45 | G19: =+D19*(1+0.85) -> 216.45 | H19: 0.4
... B21: 150 | C21: 50000 | D21: 96 | E21: =+D21/C21 -> 0.00192 | F21: =+D21*(1+0.85) -> 177.6 | G21: =+D21*(1+0.85) -> 177.6 | H21: 0.4
B22: 150 | C22: 100000 | D22: 89 | E22: =+D22/C22 -> 0.00089 | F22: =+D22*(1+0.75) -> 155.75 | G22: =+D22*(1+0.75) -> 155.75 | H22: 0.4
B23: 125 | C23: 1000 | D23: 375 | E23: =+D23/C23 -> 0.375 | F23: =+D23*(1+0.85) -> 693.75 | G23: =+D23*(1+0.85) -> 693.75 | H23: 0.4
B24: 125 | C24: 2000 | D24: 204 | E24: =+D24/C24 -> 0.102 | F24: =+D24*(1+0.85) -> 377.4 | G24: =+D24*(1+0.85) -> 377.4 | H24: 0.4
B25: 125 | C25: 2500 | D25: 149 | E25: =+D25/C25 -> 0.0596 | F25: =+D25*(1+0.85) -> 275.65 | G25: =+D25*(1+0.85) -> 275.65 | H25: 0.4
B26: 125 | C26: 5000 | D26: 127 | E26: =+D26/C26 -> 0.0254 | F26: =+D26*(1+0.85) -> 234.95 | G26: =+D26*(1+0.85) -> 234.95 | H26: 0.4
B27: 125 | C27: 10000 | D27: 115 | E27: =+D27/C27 -> 0.0115 | F27: =+D27*(1+0.85) -> 212.75 | G27: =+D27*(1+0.85) -> 212.75 | H27: 0.4
B28: 125 | C28: 20000 | D28: 102 | E28: =+D28/C28 -> 0.0051 | F28: =+D28*(1+0.85) -> 188.7 | G28: =+D28*(1+0.85) -> 188.7 | H28: 0.4
B29: 100 | C29: 1000 | D29: 375 | E29: =+D29/C29 -> 0.375 | F29: =+D29*(1+0.85) -> 693.75 | G29: =+D29*(1+0.85) -> 693.75 | H29: 0.4
B30: 100 | C30: 2000 | D30: 199 | E30: =+D30/C30 -> 0.0995 | F30: =+D30*(1+0.85) -> 368.15 | G30: =+D30*(1+0.85) -> 368.15 | H30: 0.4
B31: 100 | C31: 2500 | D31: 145 | E31: =+D31/C31 -> 0.058 | F31: =+D31*(1+0.85) -> 268.25 | G31: =+D31*(1+0.85) -> 268.25 | H31: 0.4
B32: 100 | C32: 5000 | D32: 120 | E32: =+D32/C32 -> 0.024 | F32: =+D32*(1+0.85) -> 222 | G32: =+D32*(1+0.85) -> 222 | H32: 0.4
B33: 100 | C33: 10000 | D33: 111 | E33: =+D33/C33 -> 0.0111 | F33: =+D33*(1+0.85) -> 205.35 | G33: =+D33*(1+0.85) -> 205.35 | H33: 0.4
B34: 100 | C34: 20000 | D34: 98 | E34: =+D34/C34 -> 0.0049 | F34: =+D34*(1+0.85) -> 181.3 | G34: =+D34*(1+0.85) -> 181.3 | H34: 0.4
B35: 100 | C35: 50000 | D35: 91 | E35: =+D35/C35 -> 0.00182 | F35: =+D35*(1+0.85) -> 168.35 | G35: =+D35*(1+0.85) -> 168.35 | H35: 0.4
B36: 100 | C36: 100000 | D36: 84 | E36: =+D36/C36 -> 0.00084 | F36: =+D36*(1+0.75) -> 147 | G36: =+D36*(1+0.75) -> 147 | H36: 0.4
B37: 75 | C37: 1000 | D37: 375 | E37: =+D37/C37 -> 0.375 | F37: =+D37*(1+0.85) -> 693.75 | G37: =+D37*(1+0.85) -> 693.75 | H37: 0.4
B38: 75 | C38: 2000 | D38: 193 | E38: =+D38/C38 -> 0.0965 | F38: =+D38*(1+0.85) -> 357.05 | G38: =+D38*(1+0.85) -> 357.05 | H38: 0.4
B39: 75 | C39: 2500 | D39: 140 | E39: =+D39/C39 -> 0.056 | F39: =+D39*(1+0.85) -> 259 | G39: =+D39*(1+0.85) -> 259 | H39: 0.4
B40: 75 | C40: 5000 | D40: 116 | E40: =+D40/C40 -> 0.0232 | F40: =+D40*(1+0.85) -> 214.6 | G40: =+D40*(1+0.85) -> 214.6 | H40: 0.4
B41: 75 | C41: 10000 | D41: 105 | E41: =+D41/C41 -> 0.0105 | F41: =+D41*(1+0.85) -> 194.25 | G41: =+D41*(1+0.85) -> 194.25 | H41: 0.4
B42: 75 | C42: 20000 | D42: 94 | E42: =+D42/C42 -> 0.0047 | F42: =+D42*(1+0.85) -> 173.9 | G42: =+D42*(1+0.85) -> 173.9 | H42: 0.4
B43: 75 | C43: 50000 | D43: 87 | E43: =+D43/C43 -> 0.00174 | F43: =+D43*(1+0.85) -> 160.95 | G43: =+D43*(1+0.85) -> 160.95 | H43: 0.4
B44: 75 | C44: 100000 | D44: 80 | E44: =+D44/C44 -> 0.0008 | F44: =+D44*(1+0.75) -> 140 | G44: =+D44*(1+0.75) -> 140 | H44: 0.4
...

Sheet tarifas Excel COPER
A1: M.P | B1: 5.12 | L1: 17 | N1: 210 | O1: 26 | R1: 239
A3: KG FAB. | B3: 50 | C3: 60 | D3: 70 | E3: 80 | F3: 90 | G3: 100 | H3: 125 | I3: 130 | J3: 140 | K3: 150 | L3: 160 | M3: 170 | N3: 180 | O3: 190 | P3: 200 | Q3: 210 | R3: 220
A4: TIEMPO
A5: PRECIO M.O. | B5: =(B4/60)*R1/B3 -> 0 | C5: =(C4/60)*R1/C3 -> 0 | D5: =(D4/60)*R1/D3 -> 0 | E5: =(E4/60)*R1/E3 -> 0 | F5: =(F4/60)*R1/F3 -> 0 | G5: =(G4/60)*R1/G3 -> 0 | H5: =(H4/60)*R1/H3 -> 0 | I5: =(I4/60)*R1/I3 -> 0 | J5: =(J4/60)*R1/J3 -> 0 | K5: =(K4/60)*R1/K3 -> 0 | L5: =(L4/60)*R1/L3 -> 0 | M5: =(M4/60)*R1/M3 -> 0 | N5: =(N4/60)*R1/N3 -> 0 | O5: =(O4/60)*R1/O3 -> 0 | P5: =(P4/60)*R1/P3 -> 0 | Q5: =(Q4/60)*R1/Q3 -> 0 | R5: =(R4/60)*R1/R3 -> 0
A6: ANALISIS 42€ | B6: =Q1/B3 -> 0 | C6: =Q1/C3 -> 0 | D6: =Q1/D3 -> 0 | E6: =Q1/E3 -> 0 | F6: =Q1/F3 -> 0 | G6: =Q1/G3 -> 0 | H6: =Q1/H3 -> 0 | I6: =Q1/I3 -> 0 | J6: =Q1/J3 -> 0 | K6: =Q1/K3 -> 0 | L6: =Q1/L3 -> 0 | M6: =Q1/M3 -> 0 | N6: =Q1/N3 -> 0 | O6: =Q1/O3 -> 0 | P6: =Q1/P3 -> 0 | Q6: =Q1/Q3 -> 0 | R6: =Q1/R3 -> 0
A7: ANALISIS 68€ | B7: =P1/B3 -> 0 | C7: =P1/C3 -> 0 | D7: =P1/D3 -> 0 | E7: =P1/E3 -> 0 | F7: =P1/F3 -> 0 | G7: =P1/G3 -> 0 | H7: =P1/H3 -> 0 | I7: =P1/I3 -> 0 | J7: =P1/J3 -> 0 | K7: =P1/K3 -> 0 | L7: =P1/L3 -> 0 | M7: =P1/M3 -> 0 | N7: =P1/N3 -> 0 | O7: =P1/O3 -> 0 | P7: =P1/P3 -> 0 | Q7: =P1/Q3 -> 0 | R7: =P1/R3 -> 0
A8: BIDON 100Kg. | B8: =O1/B3 -> 0.52 | C8: =O1/C3 -> 0.43333333 | D8: =O1/D3 -> 0.37142857 | E8: =P1/E3 -> 0 | F8: =O1/F3 -> 0.28888889 | G8: =O1/G3 -> 0.26 | H8: =O1*2/H3 -> 0.416 | I8: =O1*2/I3 -> 0.4 | J8: =O1*2/J3 -> 0.37142857 | K8: =O1*2/K3 -> 0.34666667 | L8: =O1*2/L3 -> 0.325 | M8: =O1*2/M3 -> 0.30588235 | N8: =O1*2/N3 -> 0.28888889 | O8: =O1*2/O3 -> 0.27368421 | P8: =O1*2/P3 -> 0.26 | Q8: =O1*2/Q3 -> 0.24761905 | R8: =O1*3/R3 -> 0.35454545
A9: BIDON 1000Kg.
A10: PALET EURO. | H10: =M1/H3 -> 0 | I10: =M1/I3 -> 0 | J10: =M1/J3 -> 0 | K10: =M1/K3 -> 0 | L10: =M1/L3 -> 0 | M10: =M1/M3 -> 0 | N10: =M1/N3 -> 0 | O10: =M1/O3 -> 0 | P10: =M1/P3 -> 0 | Q10: =M1/Q3 -> 0 | R10: =M1/R3 -> 0
A11: TRANSPORTE | H11: =L1/H3 -> 0.136 | I11: =L1/I3 -> 0.13076923 | J11: =L1/J3 -> 0.12142857 | K11: =L1/K3 -> 0.11333333 | L11: =L1/L3 -> 0.10625 | M11: =L1/M3 -> 0.1 | N11: =L1/N3 -> 0.094444444 | O11: =L1/O3 -> 0.089473684 | P11: =L1/P3 -> 0.085 | Q11: =L1/Q3 -> 0.080952381 | R11: =L1/R3 -> 0.077272727
A12: SUBTOTAL | B12: =SUM(B1+B5+B6+B7+B8) -> 5.64 | C12: =(B1+C5+C6+C7+C8+C9+C10+C11) -> 5.5533333 | D12: =(B1+D5+D6+D7+D8+D9+D10+D11) -> 5.4914286 | E12: =(B1+E5+E6+E7+E8+E9+E10+E11) -> 5.12 | F12: =(B1+F5+F6+F7+F8+F9+F10+F11) -> 5.4088889 | G12: =(B1+G5+G6+G7+G8+G9+G10+G11) -> 5.38 | H12: =(B1+H5+H6+H7+H8+H9+H10+H11) -> 5.672 | I12: =(B1+I5+I6+I7+I8+I9+I10+I11) -> 5.6507692 | J12: =(B1+J5+J6+J7+J8+J9+J10+J11) -> 5.6128571 | K12: =(B1+K5+K6+K7+K8+K9+K10+K11) -> 5.58 | L12: =(B1+L5+L6+L7+L8+L9+L10+L11) -> 5.55125 | M12: =(B1+M5+M6+M7+M8+M9+M10+M11) -> 5.5258824 | N12: =(B1+N5+N6+N7+N8+N9+N10+N11) -> 5.5033333 | O12: =(B1+O5+O6+O7+O8+O9+O10+O11) -> 5.4831579 | P12: =(B1+P5+P6+P7+P8+P9+P10+P11) -> 5.465 | Q12: =(B1+Q5+Q6+Q7+Q8+Q9+Q10+Q11) -> 5.4485714 | R12: =(B1+R5+R6+R7+R8+R9+R10+R11) -> 5.5518182
A13: MERMA 8% | B13: =(B12*8%) -> 0.4512 | C13: =(C12*8%) -> 0.44426667 | D13: =(D12*8%) -> 0.43931429
A14: MERMA 5% | E14: =E12*5% -> 0.256 | F14: =F12*5% -> 0.27044444 | G14: =G12*5% -> 0.269 | H14: =H12*5% -> 0.2836 | I14: =I12*5% -> 0.28253846 | J14: =J12*5% -> 0.28064286 | K14: =K12*5% -> 0.279 | L14: =L12*5% -> 0.2775625 | ... R14: =R12*5% -> 0.27759091
A15: TOTAL 1 | B15: =(B12+B13) -> 6.0912 | C15: =(C12+C13) -> 5.9976 | D15: =(D12+D13) -> 5.9307429 | E15: =(E12+E14) -> 5.376 | F15: =(F12+F14) -> 5.6793333 | G15: =G12+G14 -> 5.649 | H15: =H12+H14 -> 5.9556 | I15: =I12+I14 -> 5.9333077 | J15: =J12+J14 -> 5.8935 | K15: =K12+K14 -> 5.859 | L15: =L12+L14 -> 5.8288125 | M15: =M12+M14 -> 5.8021765 | N15: =N12+N14 -> 5.7785 | ... R15: =R12+R14 -> 5.8294091
A16: RESIDUOS | B16: =B15*2.5% -> 0.15228 | C16: =C15*2.5% -> 0.14994 | D16: =D15*2.5% -> 0.14826857 | E16: =E15*2.5% -> 0.1344 | F16: =F15*2.5% -> 0.14198333 | G16: =G15*2.5% -> 0.141225 | H16: =H15*2.5% -> 0.14889 | I16: =I15*2.5% -> 0.14833269 | J16: =J15*2.5% -> 0.1473375 | K16: =K15*3% -> 0.17577 | L16: =L15*2.5% -> 0.14572031 | M16: =M15*2.5% -> 0.14505441 | N16: =N15*2.5% -> 0.1444625 | O16: =O15*2.5% -> 0.14393289 | P16: =P15*2.5% -> 0.14345625 | Q16: =Q15*2.5% -> 0.143025 | R16: =R15*2.5% -> 0.14573523
A17: TOTAL 2 | B17: =(B15+B16) -> 6.24348 | C17: =(C15+C16) -> 6.14754 | D17: =(D15+D16) -> 6.0790114 | E17: =(E15+E16) -> 5.5104 | F17: =(F15+F16) -> 5.8213167 | G17: =(G15+G16) -> 5.790225 | H17: =(H15+H16) -> 6.10449 | I17: =(I15+I16) -> 6.0816404 | ... R17: =(R15+R16) -> 5.9751443
A20: KG FAB. | B20: 250 | C20: 275 | D20: 300 | E20: 340 | F20: 350 | G20: 375 | H20: 400 | I20: 430 | J20: 450 | K20: 475 | L20: 500 | M20: 525 | N20: 550 | O20: 575 | P20: 600 | Q20: 625 | R20: 650
A21: TIEMPO
A22: PRECIO M.O. | B22: =(B21/60)*R1/B20 -> 0 | C22: =(C21/60)*R1/C20 -> 0 | D22: =(D21/60)*R1/D20 -> 0 | E22: =(E21/60)*R1/E20 -> 0 | F22: =(F21/60)*R1/F20 -> 0 | G22: =(G21/60)*R1/G20 -> 0 | H22: =(H21/60)*R1/H20 -> 0 | I22: =(I21/60)*R1/I20 -> 0 | J22: =(J21/60)*R1/J20 -> 0 | K22: =(K21/60)*R1/K20 -> 0 | L22: =(L21/60)*R1/L20 -> 0 | M22: =(M21/60)*R1/M20 -> 0 | N22: =(N21/60)*R1/N20 -> 0 | O22: =(O21/60)*R1/O20 -> 0 | P22: =(P21/60)*R1/P20 -> 0 | Q22: =(Q21/60)*R1/Q20 -> 0 | R22: =(R21/60)*R1/R20 -> 0
A23: ANALISIS 42€ | B23: =Q1/B20 -> 0 | C23: =Q1/C20 -> 0 | D23: =Q1/D20 -> 0 | E23: =Q1/E20 -> 0 | F23: =Q1/F20 -> 0 | G23: =Q1/G20 -> 0 | H23: =Q1/H20 -> 0 | I23: =Q1/I20 -> 0 | J23: =Q1/J20 -> 0 | K23: =Q1/K20 -> 0 | L23: =Q1/L20 -> 0 | M23: =Q1/M20 -> 0 | N23: =Q1/N20 -> 0 | O23: =Q1/O20 -> 0 | P23: =Q1/P20 -> 0 | Q23: =Q1/Q20 -> 0 | R23: =Q1/R20 -> 0
A24: ANALISIS 68€ | B24: =P1/B20 -> 0 | C24: =P1/C20 -> 0 | D24: =P1/D20 -> 0 | E24: =P1/E20 -> 0 | F24: =P1/F20 -> 0 | G24: =P1/G20 -> 0 | H24: =P1/H20 -> 0 | I24: =P1/I20 -> 0 | J24: =P1/J20 -> 0 | K24: =P1/K20 -> 0 | L24: =P1/L20 -> 0 | M24: =P1/M20 -> 0 | N24: =P1/N20 -> 0 | O24: =P1/O20 -> 0 | P24: =P1/P20 -> 0 | Q24: =P1/Q20 -> 0 | R24: =P1/R20 -> 0
A25: BIDON 100Kg. | B25: =O1*3/B20 -> 0.312 | C25: =O1*3/C20 -> 0.28363636 | D25: =O1*3/D20 -> 0.26 | E25: =O1*4/E20 -> 0.30588235 | F25: =O1*4/F20 -> 0.29714286 | G25: =O1*4/G20 -> 0.27733333 | H25: =O1*4/H20 -> 0.26 | K25: =O1*5/K20 -> 0.27368421 | M25: =O1*5/M20 -> 0.24761905 | N25: =O1*6/N20 -> 0.28363636 | O25: =O1*6/O20 -> 0.27130435 | P25: =O1*6/P20 -> 0.26 | Q25: =O1*6/Q20 -> 0.2496 | R25: =O1*7/R20 -> 0.28
A26: BIDON 1000Kg. | I26: =M3/I20 -> 0.39534884 | J26: =N1/J20 -> 0.46666667 | L26: =N1/L20 -> 0.42
A27: PALET EURO. | B27: =M1/B20 -> 0 | C27: =M1/C20 -> 0 | D27: =M1/D20 -> 0 | E27: =M1/E20 -> 0 | F27: =M1*2/F20 -> 0 | G27: =M1*2/G20 -> 0 | H27: =M1*2/H20 -> 0 | I27: =M1*2/I20 -> 0 | J27: =M1*2/J20 -> 0 | K27: =M1*2/K20 -> 0 | L27: =M1*2/L20 -> 0 | M27: =M1*2/M20 -> 0 | N27: =M1*2/N20 -> 0 | O27: =M1*2/O20 -> 0 | P27: =M1*2/P20 -> 0 | Q27: =M1*2/Q20 -> 0 | R27: =M1*3/R20 -> 0
A28: TRANSPORTE | B28: =L1/B20 -> 0.068 | C28: =L1/C20 -> 0.061818182 | D28: =L1/D20 -> 0.056666667 | E28: =L1*2/E20 -> 0.1 | F28: =L1*2/F20 -> 0.097142857 | G28: =L1*2/G20 -> 0.090666667 | H28: =L1*2/H20 -> 0.085 | I28: =L1/I20 -> 0.039534884 | J28: =L1/J20 -> 0.037777778 | K28: =L1*2/K20 -> 0.071578947 | L28: =L1/L20 -> 0.034 | M28: =L1*2/M20 -> 0.064761905 | N28: =L1*2/N20 -> 0.061818182 | O28: =L1*2/O20 -> 0.059130435 | P28: =L1*2/P20 -> 0.056666667 | Q28: =L1*2/Q20 -> 0.0544 | R28: =L1*2/R20 -> 0.052307692
A29: SUBTOTAL | B29: =B1+B22+B23+B24+B25+B26+B27+B28 -> 5.5 | C29: =B1+C22+C23+C24+C25+C26+C27+C28 -> 5.4654545 | D29: =B1+D22+D23+D24+D25+D26+D27+D28 -> 5.4366667 | E29: =B1+E22+E23+E24+E25+E26+E27+E28 -> 5.5258824 | F29: =B1+F22+F23+F24+F25+F26+F27+F28 -> 5.5142857 | G29: =B1+G22+G23+G24+G25+G26+G27+G28 -> 5.488 | H29: =B1+H22+H23+H24+H25+H26+H27+H28 -> 5.465 | I29: =B1+I22+I23+I24+I25+I26+I27+I28 -> 5.5548837 | J29: =B1+J22+J23+J24+J25+J26+J27+J28 -> 5.6244444 | K29: =B1+K22+K23+K24+K25+K26+K27+K28 -> 5.4652632 | L29: =B1+L22+L23+L24+L25+L26+L27+L28 -> 5.574 | M29: =B1+M22+M23+M24+M25+M26+M27+M28 -> 5.432381 | N29: =B1+N22+N23+N24+N25+N26+N27+N28 -> 5.4654545 | O29: =B1+O22+O23+O24+O25+O26+O27+O28 -> 5.4504348 | P29: =B1+P22+P23+P24+P25+P26+P27+P28 -> 5.4366667 | Q29: =B1+Q22+Q23+Q24+Q25+Q26+Q27+Q28 -> 5.424 | R29: =B1+R22+R23+R24+R25+R26+R27+R28 -> 5.4523077
A30: MERMA 8%
A31: MERMA 5% | B31: =B29*5% -> 0.275 | C31: =C29*5% -> 0.27327273 | D31: =D29*5% -> 0.27183333 | E31: =E29*5% -> 0.27629412 | F31: =F29*5% -> 0.27571429 | G31: =G29*5% -> 0.2744 | H31: =H29*5% -> 0.27325 | I31: =I29*5% -> 0.27774419 | ... R31: =R29*5% -> 0.27261538
A32: TOTAL 1 | B32: =SUM(B29:B31) -> 5.775 | C32: =SUM(C29:C31) -> 5.7387273 | D32: =SUM(D29:D31) -> 5.7085 | E32: =SUM(E29:E31) -> 5.8021765 | F32: =SUM(F29:F31) -> 5.79 | G32: =SUM(G29:G31) -> 5.7624 | H32: =SUM(H29:H31) -> 5.73825 | I32: =SUM(I29:I31) -> 5.8326279 | ... R32: =SUM(R29:R31) -> 5.7249231
A33: RESIDUOS | B33: =B32*2.5% -> 0.144375 | C33: =C32*2.5% -> 0.14346818 | D33: =D32*2.5% -> 0.1427125 | E33: =E32*2.5% -> 0.14505441 | F33: =F32*2.5% -> 0.14475 | G33: =G32*2.5% -> 0.14406 | H33: =H32*2.5% -> 0.14345625 | I33: =I32*2.5% -> 0.1458157 | ... K33: =K32*2.5% -> 0.14346316 | L33: =L32*3% -> 0.175581 | M33: =M32*2.5% -> 0.1426 | N33: =N32*2.5% -> 0.14346818 | O33: =O32*2.5% -> 0.14307391 | P33: =P32*2.5% -> 0.1427125 | Q33: =Q32*2.5% -> 0.14238 | R33: =R32*2.5% -> 0.14312308
A34: TOTAL 2 | B34: =SUM(B32:B33) -> 5.919375 | C34: =SUM(C32:C33) -> 5.8821955 | D34: =SUM(D32:D33) -> 5.8512125 | E34: =SUM(E32:E33) -> 5.9472309 | F34: =SUM(F32:F33) -> 5.93475 | G34: =SUM(G32:G33) -> 5.90646 | H34: =SUM(H32:H33) -> 5.8817062 | I34: =SUM(I32:I33) -> 5.9784436 | ... R34: =SUM(R32:R33) -> 5.8680462
A35: M.P | B35: =B1 -> 5.12 | C35: =C1 -> 0 | L35: =L1 -> 17 | N35: =N1 -> 210 | O35: =O1 -> 26 | R35: =R1 -> 239
A37: KG FAB. | B37: 675 | C37: 700 | D37: 725 | E37: 750 | F37: 775 | G37: 800 | H37: 850 | I37: 900 | J37: 950 | K37: 1000 | L37: 1050 | M37: 1100 | N37: 1150 | O37: 1200 | P37: 1250 | Q37: 1300 | R37: 1350
A38: TIEMPO
A39: PRECIO M.O. | B39: =(B38/60)*R1/B37 -> 0 | C39: =(C38/60)*R1/C37 -> 0 | D39: =(D38/60)*R1/D37 -> 0 | E39: =(E38/60)*R1/E37 -> 0 | F39: =(F38/60)*R1/F37 -> 0 | G39: =(G38/60)*R1/G37 -> 0 | H39: =(H38/60)*R1/H37 -> 0 | I39: =(I38/60)*R1/I37 -> 0 | J39: =(J38/60)*R1/J37 -> 0 | K39: =(K38/60)*R1/K37 -> 0 | L39: =(L38/60)*R1/L37 -> 0 | M39: =(M38/60)*R1/M37 -> 0 | N39: =(N38/60)*R1/N37 -> 0 | O39: =(O38/60)*R1/O37 -> 0 | P39: =(P38/60)*R1/P37 -> 0 | Q39: =(Q38/60)*R1/Q37 -> 0 | R39: =(R38/60)*R1/R37 -> 0
A40: ANALISIS 42€ | B40: =Q1/B37 -> 0 | C40: =Q1/C37 -> 0 | D40: =Q1/D37 -> 0 | E40: =Q1/E37 -> 0 | F40: =Q1/F37 -> 0 | G40: =Q1/G37 -> 0 | H40: =Q1/H37 -> 0 | I40: =Q1/I37 -> 0 | J40: =Q1/J37 -> 0 | K40: =Q1/K37 -> 0 | L40: =Q1/L37 -> 0 | M40: =Q1/M37 -> 0 | N40: =Q1/N37 -> 0 | O40: =Q1/O37 -> 0 | P40: =Q1/P37 -> 0 | Q40: =Q1/Q37 -> 0 | R40: =Q1/R37 -> 0
A41: ANALISIS 68€ | B41: =P1/B37 -> 0 | C41: =P1/C37 -> 0 | D41: =P1/D37 -> 0 | E41: =P1/E37 -> 0 | F41: =P1/F37 -> 0 | G41: =P1/G37 -> 0 | H41: =P1/H37 -> 0 | I41: =P1/I37 -> 0 | J41: =P1/J37 -> 0 | K41: =P1/K37 -> 0 | L41: =P1/L37 -> 0 | M41: =P17/M37 -> 0.0053470057 | N41: =P1/N37 -> 0 | O41: =P1/O37 -> 0 | P41: =P1/P37 -> 0 | Q41: =P1/Q37 -> 0 | R41: =P1/R37 -> 0
A42: BIDON 100Kg. | D42: =O1*8/D37 -> 0.28689655 | E42: =O1*8/E37 -> 0.27733333 | F42: =O1*8/F37 -> 0.2683871 | H42: =O1*9/H37 -> 0.27529412 | I42: =O1*9/I37 -> 0.26 | J42: =O1*10/J37 -> 0.27368421 | L42: =O1*11/L37 -> 0.27238095 | M42: =O1*11/M37 -> 0.26 | N42: =O1*12/N37 -> 0.27130435 | O42: =O1*12/O37 -> 0.26 | P42: =O1*13/P37 -> 0.2704 | Q42: =O1*13/Q37 -> 0.26 | R42: =O1*14/R37 -> 0.26962963
A43: BIDON 1000Kg. | B43: =N35/B37 -> 0.31111111 | C43: =N35/C37 -> 0.3 | G43: =N35/G37 -> 0.2625 | K43: =N35/K37 -> 0.21
A44: PALET EURO. | B44: =M1/B37 -> 0 | C44: =M1/C37 -> 0 | D44: =M1/D37 -> 0 | E44: =M1/E37 -> 0 | F44: =M1*2/F37 -> 0 | G44: =M1*2/G37 -> 0 | H44: =M1*2/H37 -> 0 | I44: =M1*2/I37 -> 0 | J44: =M1*2/J37 -> 0 | K44: =M1*2/K37 -> 0 | L44: =M1*2/L37 -> 0 | M44: =M1*2/M37 -> 0 | N44: =M1*2/N37 -> 0 | O44: =M1*2/O37 -> 0 | P44: =M1*2/P37 -> 0 | Q44: =M1*2/Q37 -> 0 | R44: =M1*3/R37 -> 0
...

Sheet Gl
A1: Concepto | B1: Definición
A2: Envasado | B2: El cliente aporta el producto a granel; Jumsa solo realiza el envasado.
A3: Bulk | B3: Producción de la fórmula; el cliente se encarga del envasado.
A4: Bulk + envasado | B4: Producción de la fórmula + envasado
A5: Full Service | B5: Servicio completo: fórmula + fabricación + envasado + logística.
A7: Origen MP | B7: Indica quién aporta las materias primas: Cliente, Jumsa o Mixto.
A8: Estado de Fórmula | B8: Clasifica si el producto es nuevo, repetido, actualización de costes o regular.
A9: Cliente aporta MP | B9: El cliente envía las materias primas; reduce precio y margen.
